<?xml version="1.0"?>
<mujoco>
	<option gravity="0 0 -9.81" integrator="RK4" timestep="0.02"/>
    <worldbody>
        <!-- <body name="robot" pos="0 0 &#45;5.0" mocap="true"> -->
        <body name="robot" pos="7.5 0 0">
            <joint axis="1 0 0" damping="0.5" name="slide_robot_x" pos="0 0 0" type="slide"/>
            <joint axis="0 1 0" damping="0.5" name="slide_robot_y" pos="0 0 0" type="slide"/>
            <joint axis="0 0 1" damping="1.0" name="slide_robot_z" pos="0 0 0" type="slide"/>
            <geom mass="25.0" pos="0 30 5" rgba="0.5 0.5 0.5 1.0" size="3.5 5.0" type="cylinder"/>
        </body> 

        <body name="ball" pos="10 -5 0">
            <joint axis="1 0 0" damping="0.5" name="slide_ball_x" pos="0 0 0" type="slide"/>
            <joint axis="0 1 0" damping="0.5" name="slide_ball_y" pos="0 0 0" type="slide"/>
            <joint axis="0 0 1" damping="1.0" name="slide_ball_z" pos="0 0 0" type="slide"/>
            <geom mass="1.0" pos="0 0 2" rgba="1 1 10 1" size="2.0" type="sphere"/>
        </body>

        <body name="ball2" pos="-10 -5 0">
            <joint axis="1 0 0" damping="0.5" name="slide_ball2_x" pos="0 0 0" type="slide"/>
            <joint axis="0 1 0" damping="0.5" name="slide_ball2_y" pos="0 0 0" type="slide"/>
            <joint axis="0 0 1" damping="1.0" name="slide_ball2_z" pos="0 0 0" type="slide"/>
            <geom mass="1.0" pos="0 0 2" rgba="1 10 1 1" size="2.0" type="sphere"/>
        </body>
        
        <body name="ball3" pos="0 8.5 0">
            <joint axis="1 0 0" damping="0.5" name="slide_ball3_x" pos="0 0 0" type="slide"/>
            <joint axis="0 1 0" damping="0.5" name="slide_ball3_y" pos="0 0 0" type="slide"/>
            <joint axis="0 0 1" damping="1.0" name="slide_ball3_z" pos="0 0 0" type="slide"/>
            <geom mass="1.0" pos="0 0 2" rgba="10 1 1 1" size="2.0" type="sphere"/>
        </body>
        
        <body name="floor" pos="0 0 -0.1">
            <geom condim="3" size="90 60 0.1" friction="0.0 0.0 0.0" rgba="0.2 1.5 0.2 1" type="box"/>
        </body>

        <body name="wall1" pos="0 60 7.5">
            <geom condim="3" size="90 0.2 7.5" friction="0.0 0.0 0.0" rgba="1.5 0.2 2.5 0.2" type="box"/>
        </body>
        
        <body name="wall2" pos="90 0 7.5">
            <geom condim="3" size="0.2 60 7.5" friction="0.0 0.0 0.0" rgba="1.5 0.2 2.5 0.2" type="box"/>
        </body>

        <body name="wall3" pos="-90 0 7.5">
            <geom condim="3" size="0.2 60 7.5" friction="0.0 0.0 0.0" rgba="1.5 0.2 2.5 0.2" type="box"/>
        </body>

        <body name="wall4" pos="0 -60 7.5">
            <geom condim="3" size="90 0.2 7.5" friction="0.0 0.0 0.0" rgba="1.5 0.2 2.5 0.2" type="box"/>
        </body>

    </worldbody>
    <actuator>
        <velocity gear="25.0" joint="slide_robot_x"/>
        <velocity gear="25.0" joint="slide_robot_y"/>
        <velocity gear="10.0" joint="slide_robot_z"/>
    </actuator>
</mujoco>
